Workbook

Sheet Як заповнювати
B2: Elvin — питання технологу
B3: Відповіді переносяться у правила фабрики (rules/wardrobe-rules.js). Elvin сам правила не змінює.
B5: Що заповнювати | C5: Лише жовті клітинки на аркуші «Питання»: «Відповідь технолога», «Значення, мм», «Хто відповів», «Дата», «Статус», «Коментар».
B6: Відповідь | C6: Коротко і однозначно. Якщо залежить від креслення — опишіть, від чого саме.
B7: Значення, мм | C7: Лише числа в мм, у форматі з підказки в колонці. Невідоме — залиште порожнім, не «приблизно».
B8: Статус | C8: Відкрито → Відповідь отримано → Внесено в Elvin. «Потрібен скрипт BAZIS» — якщо відповідь можна дати лише перевіреним скриптом.
B9: Пріоритет | C9: Високий — блокує розрахунок більшості шаф. Середній — потрібен для повного коду BAZIS. Низький — можна пізніше.
B10: Фільтр | C10: У заголовках є фільтри: можна показати лише відкриті питання або один розділ.
B11: Приклад рядка | C11: Питання: «ХДФ у паз: стандартний відступ паза від заднього краю?» → Відповідь: «Стандарт 10 мм, для глибоких шаф 16 мм» · Значення: 10 · Хто: Іван · Дата: 16.10.2026 · Статус: Відповідь отримано. (Це лише приклад формату, не реальна відповідь.)
B13: Жовта клітинка | C13: — поле для заповнення

Sheet Зведення
A1: Зведення по питаннях
A3: Розділ | B3: Усього | C3: Відкрито | D3: Відповідь отримано | E3: Потрібен скрипт BAZIS | F3: Внесено в Elvin | G3: Відкрито з пріоритетом «Високий»
A4: Корпус | B4: =COUNTIF(Питання!$B$2:$B$200,A4) -> 9 | C4: =COUNTIFS(Питання!$B$2:$B$200,A4,Питання!$L$2:$L$200,"Відкрито") -> 5 | D4: =COUNTIFS(Питання!$B$2:$B$200,A4,Питання!$L$2:$L$200,"Відповідь отримано") -> 0 | E4: =COUNTIFS(Питання!$B$2:$B$200,A4,Питання!$L$2:$L$200,"Потрібен скрипт BAZIS") -> 0 | F4: =COUNTIFS(Питання!$B$2:$B$200,A4,Питання!$L$2:$L$200,"Внесено в Elvin") -> 4 | G4: =COUNTIFS(Питання!$B$2:$B$200,A4,Питання!$L$2:$L$200,"Відкрито",Питання!$C$2:$C$200,"Високий") -> 4
A5: Полиці | B5: =COUNTIF(Питання!$B$2:$B$200,A5) -> 5 | C5: =COUNTIFS(Питання!$B$2:$B$200,A5,Питання!$L$2:$L$200,"Відкрито") -> 4 | D5: =COUNTIFS(Питання!$B$2:$B$200,A5,Питання!$L$2:$L$200,"Відповідь отримано") -> 0 | E5: =COUNTIFS(Питання!$B$2:$B$200,A5,Питання!$L$2:$L$200,"Потрібен скрипт BAZIS") -> 0 | F5: =COUNTIFS(Питання!$B$2:$B$200,A5,Питання!$L$2:$L$200,"Внесено в Elvin") -> 1 | G5: =COUNTIFS(Питання!$B$2:$B$200,A5,Питання!$L$2:$L$200,"Відкрито",Питання!$C$2:$C$200,"Високий") -> 1
A6: Перегородки | B6: =COUNTIF(Питання!$B$2:$B$200,A6) -> 3 | C6: =COUNTIFS(Питання!$B$2:$B$200,A6,Питання!$L$2:$L$200,"Відкрито") -> 3 | D6: =COUNTIFS(Питання!$B$2:$B$200,A6,Питання!$L$2:$L$200,"Відповідь отримано") -> 0 | E6: =COUNTIFS(Питання!$B$2:$B$200,A6,Питання!$L$2:$L$200,"Потрібен скрипт BAZIS") -> 0 | F6: =COUNTIFS(Питання!$B$2:$B$200,A6,Питання!$L$2:$L$200,"Внесено в Elvin") -> 0 | G6: =COUNTIFS(Питання!$B$2:$B$200,A6,Питання!$L$2:$L$200,"Відкрито",Питання!$C$2:$C$200,"Високий") -> 0
A7: Задня стінка | B7: =COUNTIF(Питання!$B$2:$B$200,A7) -> 18 | C7: =COUNTIFS(Питання!$B$2:$B$200,A7,Питання!$L$2:$L$200,"Відкрито") -> 13 | D7: =COUNTIFS(Питання!$B$2:$B$200,A7,Питання!$L$2:$L$200,"Відповідь отримано") -> 0 | E7: =COUNTIFS(Питання!$B$2:$B$200,A7,Питання!$L$2:$L$200,"Потрібен скрипт BAZIS") -> 0 | F7: =COUNTIFS(Питання!$B$2:$B$200,A7,Питання!$L$2:$L$200,"Внесено в Elvin") -> 5 | G7: =COUNTIFS(Питання!$B$2:$B$200,A7,Питання!$L$2:$L$200,"Відкрито",Питання!$C$2:$C$200,"Високий") -> 4
A8: Цоколь і ніжки | B8: =COUNTIF(Питання!$B$2:$B$200,A8) -> 5 | C8: =COUNTIFS(Питання!$B$2:$B$200,A8,Питання!$L$2:$L$200,"Відкрито") -> 5 | D8: =COUNTIFS(Питання!$B$2:$B$200,A8,Питання!$L$2:$L$200,"Відповідь отримано") -> 0 | E8: =COUNTIFS(Питання!$B$2:$B$200,A8,Питання!$L$2:$L$200,"Потрібен скрипт BAZIS") -> 0 | F8: =COUNTIFS(Питання!$B$2:$B$200,A8,Питання!$L$2:$L$200,"Внесено в Elvin") -> 0 | G8: =COUNTIFS(Питання!$B$2:$B$200,A8,Питання!$L$2:$L$200,"Відкрито",Питання!$C$2:$C$200,"Високий") -> 0
A9: Кромка | B9: =COUNTIF(Питання!$B$2:$B$200,A9) -> 5 | C9: =COUNTIFS(Питання!$B$2:$B$200,A9,Питання!$L$2:$L$200,"Відкрито") -> 5 | D9: =COUNTIFS(Питання!$B$2:$B$200,A9,Питання!$L$2:$L$200,"Відповідь отримано") -> 0 | E9: =COUNTIFS(Питання!$B$2:$B$200,A9,Питання!$L$2:$L$200,"Потрібен скрипт BAZIS") -> 0 | F9: =COUNTIFS(Питання!$B$2:$B$200,A9,Питання!$L$2:$L$200,"Внесено в Elvin") -> 0 | G9: =COUNTIFS(Питання!$B$2:$B$200,A9,Питання!$L$2:$L$200,"Відкрито",Питання!$C$2:$C$200,"Високий") -> 0
A10: Фасади | B10: =COUNTIF(Питання!$B$2:$B$200,A10) -> 5 | C10: =COUNTIFS(Питання!$B$2:$B$200,A10,Питання!$L$2:$L$200,"Відкрито") -> 2 | D10: =COUNTIFS(Питання!$B$2:$B$200,A10,Питання!$L$2:$L$200,"Відповідь отримано") -> 0 | E10: =COUNTIFS(Питання!$B$2:$B$200,A10,Питання!$L$2:$L$200,"Потрібен скрипт BAZIS") -> 0 | F10: =COUNTIFS(Питання!$B$2:$B$200,A10,Питання!$L$2:$L$200,"Внесено в Elvin") -> 3 | G10: =COUNTIFS(Питання!$B$2:$B$200,A10,Питання!$L$2:$L$200,"Відкрито",Питання!$C$2:$C$200,"Високий") -> 0
A11: Кріплення | B11: =COUNTIF(Питання!$B$2:$B$200,A11) -> 3 | C11: =COUNTIFS(Питання!$B$2:$B$200,A11,Питання!$L$2:$L$200,"Відкрито") -> 3 | D11: =COUNTIFS(Питання!$B$2:$B$200,A11,Питання!$L$2:$L$200,"Відповідь отримано") -> 0 | E11: =COUNTIFS(Питання!$B$2:$B$200,A11,Питання!$L$2:$L$200,"Потрібен скрипт BAZIS") -> 0 | F11: =COUNTIFS(Питання!$B$2:$B$200,A11,Питання!$L$2:$L$200,"Внесено в Elvin") -> 0 | G11: =COUNTIFS(Питання!$B$2:$B$200,A11,Питання!$L$2:$L$200,"Відкрито",Питання!$C$2:$C$200,"Високий") -> 0
A12: BAZIS | B12: =COUNTIF(Питання!$B$2:$B$200,A12) -> 6 | C12: =COUNTIFS(Питання!$B$2:$B$200,A12,Питання!$L$2:$L$200,"Відкрито") -> 4 | D12: =COUNTIFS(Питання!$B$2:$B$200,A12,Питання!$L$2:$L$200,"Відповідь отримано") -> 0 | E12: =COUNTIFS(Питання!$B$2:$B$200,A12,Питання!$L$2:$L$200,"Потрібен скрипт BAZIS") -> 0 | F12: =COUNTIFS(Питання!$B$2:$B$200,A12,Питання!$L$2:$L$200,"Внесено в Elvin") -> 2 | G12: =COUNTIFS(Питання!$B$2:$B$200,A12,Питання!$L$2:$L$200,"Відкрито",Питання!$C$2:$C$200,"Високий") -> 0
A13: Разом | B13: =SUM(B4:B12) -> 59 | C13: =SUM(C4:C12) -> 44 | D13: =SUM(D4:D12) -> 0 | E13: =SUM(E4:E12) -> 0 | F13: =SUM(F4:F12) -> 15 | G13: =SUM(G4:G12) -> 9
A15: Готовність, % (внесено в Elvin від усіх питань) | F15: =IF(B13=0,0,F13/B13) -> 0.25423729

Sheet Питання
A1: № | B1: Розділ | C1: Пріоритет | D1: Питання | E1: Навіщо Elvin | F1: Що зараз у правилах / відомо | G1: Варіанти | H1: Відповідь технолога | I1: Значення, мм | J1: Хто відповів | K1: Дата | L1: Статус | M1: Коментар
A2: 1 | B2: Корпус | C2: Високий | D2: Яка схема корпусу шафи стандартна: боковини стоять на суцільному дні (так у правилах) чи боковини до підлоги, а дно вкладне на цоколі (так у скрипті ТИМА ПЕТРАШ)? Коли яку застосовувати? | E2: Від цього залежать розміри боковин, дна і цоколю в кожній шафі. | F2: Правила: дно на всю ширину, боковини на дні. Еталонний скрипт: боковини до підлоги, вкладне дно на висоті 100. | G2: Боковини на дні / Боковини до підлоги / Залежить від креслення | L2: Відкрито
A3: 2 | B3: Корпус | C3: Середній | D3: Коли верх (кришка KR) накладний, а не вкладний між боковинами? Як це видно на кресленні? | E3: Розмір кришки і висота боковин. | F3: Стандарт: вкладний між боковинами. | L3: Відкрито
A4: 3 | B4: Корпус | C4: Високий | D4: Як з креслення зрозуміти, чи загальна глибина включає фасад? | E4: Формула глибини корпусу: глибина − товщина фасаду − 2 мм. | F4: Формула затверджена, але ознака на кресленні не описана. | L4: Відкрито
A5: 4 | B5: Корпус | C5: Низький | D5: Коли використовується ламінована конструкція 18+18 мм (≈37 мм) і як вона позначається на кресленні? | E5: Товщина деталей. | F5: Статус ASK: шари 18+18, клей ≈1 мм. | H5: ДСП 18 або склейка 37 мм (18 + 18 + 1 мм клею) | I5: 18 / 37 | J5: Користувач (чат) | K5: 17.10.2026 | L5: Внесено в Elvin
A6: 5 | B6: Корпус | C6: Високий | D6: Розміри секцій на кресленнях зазвичай проставлені у світлі (між деталями), по осях чи зовнішні? | E6: Elvin зараз розраховує лише розміри у світлі. | F6: Не визначено. | G6: У світлі / По осях / Зовнішні / По-різному | L6: Відкрито
A7: 6 | B7: Корпус | C7: Високий | D7: Якщо сума розмірів секцій на кресленні не збігається з габаритом на 1–3 мм: завжди питати чи є допуск? Якщо є допуск — у яку секцію переносити різницю? | E7: Зараз Elvin зупиняється і питає за будь-якої різниці. | F7: Допуск 0 мм. | L7: Відкрито
A8: 7 | B8: Полиці | C8: Високий | D8: Втоплення полиць 50 мм — від переднього краю чи від задньої стінки? | E8: У скрипті ТИМА ПЕТРАШ коментар каже «від переднього краю», а координати ставлять полицю врівень із фронтом. | F8: Elvin робить відступ від фронту. | G8: Від фронту / Від задньої стінки | L8: Відкрито
A9: 8 | B9: Полиці | C9: Середній | D9: Коли полиці втоплюються взагалі і на скільки зазвичай? | E9: Глибина полиць. | F9: Стандарт: глибина полиці = глибина корпусу. | H9: Стандарт: на всю глибину корпусу (при накладній ХДФ) | I9: 0 | J9: Користувач (чат) | K9: 16.10.2026 | L9: Внесено в Elvin
A10: 9 | B10: Полиці | C10: Середній | D10: Полиці кріпляться на конфірмати (нерухомі) чи стоять на полицетримачах (знімні)? Як це позначається? | E10: Кріплення і, можливо, довжина полиці (зазор для знімної). | F10: Не визначено. | G10: Конфірмати / Полицетримачі / По кресленню | L10: Відкрито
A11: 10 | B11: Полиці | C11: Середній | D11: Чи знімна полиця коротша за проріз? Якщо так — на скільки? | E11: Розмір POLKA. | F11: Не визначено. | L11: Відкрито
A12: 11 | B12: Полиці | C12: Низький | D12: Штанга для одягу: чи має Elvin додавати її в BAZIS? Висота під полицею, тип, кріплення. | E12: Комплектність замовлення. | F12: Не визначено. | L12: Відкрито
A13: 12 | B13: Перегородки | C13: Середній | D13: Середня стійка ST_SR завжди йде від дна до кришки? Коли стійка стоїть на полиці (між двома полицями)? | E13: Висота ST_SR. | F13: Правило: стоїть на дні, доходить до кришки. | L13: Відкрито
A14: 13 | B14: Перегородки | C14: Середній | D14: Розпорка при прольоті від 900 мм: коли саме додавати автоматично і для якої товщини ДСП? | E14: Додаткові деталі. | F14: Перевірено: ДСП 18, висота 100, ззаду під полицею, 2 шканти на торець. | L14: Відкрито
A15: 14 | B15: Перегородки | C15: Низький | D15: Максимальний проліт полиці без опори для ДСП 16 і ДСП 18? | E15: Попередження про прогин. | F15: Не визначено. | L15: Відкрито
A16: 15 | B16: Задня стінка | C16: Високий | D16: Накладна ХДФ: наскільки лист менший за корпус зверху, знизу, ліворуч, праворуч? | E16: Розмір TYL. | F16: У скрипті: знизу +2 мм від низу дна, зверху −2 мм, з боків рівно по секції. | I16: мм: верх / низ / ліво / право | L16: Відкрито | M16: Формат значення: мм: верх / низ / ліво / право
A17: 16 | B17: Задня стінка | C17: Високий | D17: Накладна ХДФ по секціях: на скільки лист заходить на стійку ST_SR і на боковину? | E17: У скрипті ТИМА ПЕТРАШ кожен лист рівно 630 мм, тобто 0 мм на стійку. | F17: Не визначено. | L17: Відкрито
A18: 17 | B18: Задня стінка | C18: Середній | D18: Коли ставити один цільний лист ХДФ замість окремих по секціях? Що вважається «малою шафою»? | E18: Кількість і розмір TYL. | F18: Окремий лист на секцію або один цільний для малої шафи. | G18: Якщо вміщується в лист 2800×2070 / Інше | L18: Відкрито
A19: 18 | B19: Задня стінка | C19: Середній | D19: Якщо одна секція більша за лист 2800×2070 — як ділити ХДФ? Де робити стик? | E19: Розкрій TYL. | F19: Лист макс. 2800×2070 мм. | L19: Відкрито
A20: 19 | B20: Задня стінка | C20: Середній | D20: ХДФ у паз: на скільки лист заходить у паз (паз 9 мм завглибшки) і який зазор? | E20: Розмір TYL у пазу. | F20: Паз 4×9 мм, ХДФ 3 мм. | L20: Відкрито
A21: 20 | B21: Задня стінка | C21: Середній | D21: ХДФ у паз: угорі паз у кришці чи ХДФ заходить під кришку? | E21: Деталі, у яких робиться паз. | F21: Паз у лівій і правій боковинах та в дні. | G21: Паз у кришці / Під кришку | H21: Паз лише з 3 боків (ліва, права, дно); ХДФ вставляється зверху за вкладну кришку | J21: Користувач (чат) | K21: 17.10.2026 | L21: Внесено в Elvin | M21: Відкрито: як при накладній кришці (у GibLab траплялось KR_PAZ)
A22: 21 | B22: Задня стінка | C22: Середній | D22: ХДФ у паз: стандартний відступ паза від заднього краю? | E22: Положення паза і глибина полиць. | F22: Дозволено 5–20 мм. | H22: 14 мм від заднього краю; паз 4 × 9 мм | I22: 14 | J22: Користувач (чат) | K22: 17.10.2026 | L22: Внесено в Elvin
A23: 22 | B23: Задня стінка | C23: Середній | D23: ХДФ у паз: максимальний розмір листа? | E23: Розкрій. | F23: Не визначено. | L23: Відкрито
A24: 23 | B24: Задня стінка | C24: Високий | D24: ХДФ у паз: надіслати перевірений скрипт BAZIS із операцією паза. | E24: Без нього Elvin не генерує паз. | F24: Паз на паузі до перевірки в BAZIS. | L24: Відкрито
A25: 24 | B25: Задня стінка | C25: Середній | D25: Вибірка (чверть): ширина і глибина? | E25: Обробка деталей. | F25: Немає даних. | I25: мм: ширина × глибина | L25: Відкрито | M25: Формат значення: мм: ширина × глибина
A26: 25 | B26: Задня стінка | C26: Середній | D26: Вибірка: у яких деталях робиться (боковини, дно, кришка, стійки)? | E26: Обробка деталей. | F26: Немає даних. | L26: Відкрито
A27: 26 | B27: Задня стінка | C27: Середній | D27: Вибірка: розмір ХДФ і чим кріпиться? | E27: Розмір TYL. | F27: Немає даних. | L27: Відкрито
A28: 27 | B28: Задня стінка | C28: Високий | D28: Вибірка: надіслати перевірений скрипт BAZIS із цією операцією. | E28: Без нього Elvin не генерує вибірку. | F28: Немає даних. | L28: Відкрито
A29: 28 | B29: Задня стінка | C29: Низький | D29: Задня стінка з ДСП: розміри відносно корпусу і кріплення? | E29: Окрема деталь. | F29: Статус ASK, кріплення не визначене. | L29: Відкрито
A30: 29 | B30: Задня стінка | C30: Середній | D30: Якщо на кресленні не вказано тип задньої стінки — що ставити за замовчуванням? | E30: Щоб Elvin не питав щоразу. | F30: Зараз Elvin питає. | G30: Накладна ХДФ / Завжди питати | L30: Відкрито
A31: 30 | B31: Цоколь і ніжки | C31: Середній | D31: Цоколь пластиковий чи з ДСП — коли який? Чи пластиковий цоколь потрібен як деталь у BAZIS? | E31: Деталь COKOL. | F31: Відомі типи: пластиковий, дерев'яний. | L31: Відкрито
A32: 31 | B32: Цоколь і ніжки | C32: Середній | D32: Ширина цоколю: між боковинами (як у скрипті, W − 2T) чи інакше, коли боковини стоять на дні? | E32: Розмір COKOL. | F32: Висота 100, відступ 20 від фронту. | L32: Відкрито
A33: 32 | B33: Цоколь і ніжки | C33: Низький | D33: Чи потрібен боковий або задній цоколь (для шафи, що стоїть окремо)? | E33: Додаткові деталі. | F33: Не визначено. | L33: Відкрито
A34: 33 | B34: Цоколь і ніжки | C34: Середній | D34: Ніжки 100 чи 150 мм — коли які? Ніжки завжди разом із цоколем? | E34: Висота опори. | F34: Розстановка ніжок затверджена (50/70/50, крок ≤500). | L34: Відкрито
A35: 34 | B35: Цоколь і ніжки | C35: Низький | D35: Низька опора ≈7 мм: точна назва фурнітури і конструкція. | E35: Зараз на паузі. | F35: Не визначено. | L35: Відкрито
A36: 35 | B36: Кромка | C36: Середній | D36: Боковини: верхній і нижній торці — KR08 завжди? А коли боковина стоїть на дні? | E36: Кромкування ST_L/ST_R. | F36: У скрипті при боковинах до підлоги верх і низ KR08. | L36: Відкрито
A37: 36 | B37: Кромка | C37: Середній | D37: Стійки ST_SR: верхній і нижній торці без кромки, перед KR08, зад BUM02 — це стандарт? | E37: Кромкування ST_SR. | F37: Так у скрипті ТИМА ПЕТРАШ. | G37: Так / Ні | L37: Відкрито
A38: 37 | B38: Кромка | C38: Середній | D38: Полиці POLKA: перед KR08, зад BUM02, бокові торці без кромки — це стандарт? А для втопленої полиці? | E38: Кромкування POLKA. | F38: Так у скрипті ТИМА ПЕТРАШ. | G38: Так / Ні | L38: Відкрито
A39: 38 | B39: Кромка | C39: Середній | D39: Вкладні дно DNO і кришка KR: перед KR08, зад BUM02, боки без кромки — це стандарт? | E39: Кромкування DNO/KR. | F39: Для суцільного дна: перед, ліво, право KR08, зад BUM02. | G39: Так / Ні | L39: Відкрито
A40: 39 | B40: Кромка | C40: Низький | D40: Цоколь COKOL: на якому торці KR08 (у скрипті торець 0)? | E40: Кромкування COKOL. | F40: У скрипті один торець KR08. | L40: Відкрито
...
